Workbook

Sheet Form Responses 1
A1: Timestamp | B1: Full Name | C1: Gender | D1: Phone Number | E1: Emergency Contact | F1: City (travelling from) | G1: State (travelling from) | H1: Accommodation (per night charges) | I1: Date of Check In (MM/DD/YYYY) | J1: No of nights of stay : 1 | K1: Upload Payment Screenshot to Confirm Accommodation | L1: Comments
A2: 46102.808 | B2: Nithin D S | C2: Male | D2: 7259874849 | E2: 9591196844 | F2: Bengaluru | G2: Karnataka | H2: Dorm Cottage – Rs 1500/- per person | I2: 6/3/2026 | J2: 2 | K2: https://drive.google.com/open?id=17xlz4SiGl6NKbL4bX2x250xWHi2tVShE
A3: 46168.3 | B3: Manoj Sundaram | C3: Male | D3: 9900239304 | E3: 9902087050 | F3: Bangalore | G3: Karnataka | H3: Bring your own Tent - Rs 700/- per spot | I3: 6/3/2026 | J3: 2 | K3: https://drive.google.com/open?id=1H3ecGj1UGZc1OUtJeIIKxfY3LMZBRIGU
A4: 46171.438 | B4: Nitin Fadthe | C4: Male | D4: 8806723534 | E4: 7972563757 | F4: Vasco | G4: Goa | H4: Dorm Cottage – Rs 1500/- per person | I4: 6/3/2026 | J4: 1 | K4: https://drive.google.com/open?id=1qsivUmQJEq-cW3nA_8Cn-7U0WkuTFUJh
A5: 46083.389 | B5: Sandeep Sudhir Kale | C5: Male | D5: 7506655137 | E5: 9420929155 | F5: Thane | G5: Maharashtra | H5: Dorm Cottage – Rs 1500/- per person | I5: 6/4/2026 | J5: 1 | K5: https://drive.google.com/open?id=1EMkXW07Y-aQrhveyF1gvRrEDaVkHmmYI
A6: 46108.738 | B6: Pooja Tanaji Budhawale | C6: Female | D6: 9975047905 | E6: 9850435652 | F6: Pune | G6: Maharashtra | H6: Dorm Cottage – Rs 1500/- per person | I6: 6/4/2026 | J6: 1 | K6: https://drive.google.com/open?id=1H3Lz0es1x6OnRgt1751eDXZHwWWCaqUB
A7: 46134.455 | B7: SUDEEP VITHAL DALVI | C7: Male | D7: 8080838036 | E7: 9137472127 | F7: MUMBAI-GHATKOPAR | G7: MAHARASHTRA | H7: Dorm Cottage – Rs 1500/- per person | I7: 6/4/2026 | J7: 2 | K7: https://drive.google.com/open?id=1Bt6ua0XjiWD5HIRB_xLevZClUJ_o8UDW
A8: 46154.63 | B8: Sagar Dombe | C8: Male | D8: 9869634142 | E8: 9869746012 | F8: Thane | G8: Maharashtra | H8: Dorm Cottage – Rs 1500/- per person | I8: 6/4/2026 | J8: 2 | K8: https://drive.google.com/open?id=18vdQRFX1s4xFazXX5dGiNWzqkRgd_a3K
A9: 46163.892 | B9: Shreyas Dev Lama | C9: Male | D9: 8130845518 | E9: Anupama - 9650063772 | F9: Mumbai | G9: Maharashtra | H9: Dorm Cottage – Rs 1500/- per person | I9: 6/4/2026 | J9: 2 | K9: https://drive.google.com/open?id=1d3jPUdAzoStqFDe9QgEaBGwzH3ZXXpp2
A10: 46164.402 | B10: Nitin Fadthe | C10: Male | D10: 8806723534 | E10: 7972563757 | F10: Vasco | G10: Goa | H10: Bamboo House – Rs 1400/- per person | I10: 6/4/2026 | J10: 1 | K10: https://drive.google.com/open?id=1I2x6QfJMSk1CKErwHNic_whVkD4ZCO6t
A11: 46165.531 | B11: Pempa Tshering Sherpa | C11: Male | D11: 7719305093 | E11: 964750435 | F11: - | G11: - | H11: Dorm Cottage – Rs 1500/- per person | I11: 6/4/2026 | J11: 2 | K11: https://drive.google.com/open?id=1NCnVezL9QVesKWI0EMuQOgfsAuC0TaAJ
A12: 46166.798 | B12: Mamta Joshi | C12: Female | D12: 9997398115 | E12: Neeraj | F12: Deesa | G12: Gujrat | H12: Dorm Cottage – Rs 1500/- per person | I12: 6/4/2026 | J12: 3 | K12: https://drive.google.com/open?id=1lWft3LUETj8O7GeeiSesOHfbIKjJmKz5
A13: 46167.755 | B13: Sudesh P Mithapelli | C13: Male | D13: 8788702298 | E13: 8830440124 | F13: Nigdi | G13: Maharashtra | H13: Dorm Cottage – Rs 1500/- per person | I13: 6/4/2026 | J13: 1 | K13: https://drive.google.com/open?id=19gp2A3F2Zvj66rOPrPfbHAFJ8vD363do
A14: 46171.433 | B14: Sreeraj V | C14: Male | D14: 7012958074 | E14: 8891802063 | F14: Kalyan | G14: Maharashtra | H14: Dorm Cottage – Rs 1500/- per person | I14: 6/4/2026 | J14: 1 | K14: https://drive.google.com/open?id=1mh3M856w03hq5Pl5zYkZCPW8zp0iClqE
A15: 46171.658 | B15: Vijayan Pillai | C15: Male | D15: 9446027379 | E15: 9446307379 | F15: Cochin | G15: Kerala | H15: Dorm Cottage – Rs 1500/- per person | I15: 6/4/2026 | J15: 1 | K15: https://drive.google.com/open?id=1FDy6ZxIqW_hHLw2hiTmurfFmykL7hyol
A16: 46175.463 | B16: Milap Shah | C16: Male | D16: 9023649791 | E16: 9023421954 | F16: Ahmedabad | G16: Gujarat | H16: Bring your own Tent - Rs 700/- per spot | I16: 6/4/2026 | J16: 1 | K16: https://drive.google.com/open?id=1dbgzCTc4Nw9oUOAaTDsnlZBJ2TvFvLKe
A17: 46099.774 | B17: Ajin P Suresh | C17: Male | D17: 8891426550 | E17: Anjana ks | F17: Kottakkal | G17: Kerala | H17: 3 person Tent - Complete Tent - Rs 3000/- | I17: 6/5/2026 | J17: 1 | K17: https://drive.google.com/open?id=1HsMAg2ZaYKTXWQwmhwapHcyxO01u6wvx
A18: 46134.505 | B18: Swapnil Pralhad Patil | C18: Male | D18: 9967022249 | E18: 9870303084 | F18: Thane | G18: Maharashtra | H18: Dorm Cottage – Rs 1500/- per person | I18: 6/5/2026 | J18: 1 | K18: https://drive.google.com/open?id=1bzwIXLtyUENywbSQpPUFQHjzQrZXHEGL
A19: 46135.866 | B19: Bhavik Solanki | C19: Male | D19: 9727046243 | E19: Amit - 7715890930 | F19: Mumbai | G19: Maharashtra | H19: Dorm Cottage – Rs 1500/- per person | I19: 6/5/2026 | J19: 1 | K19: https://drive.google.com/open?id=1VCCMZKc-Y1OB9a0faIahnnwGiC0iDQ6i
A20: 46135.867 | B20: Amit Sanjay Singh Nagarkoti | C20: Male | D20: 7715890930 | E20: 9004340694 | F20: Navi Mumbai | G20: Maharashtra | H20: Dorm Cottage – Rs 1500/- per person | I20: 6/5/2026 | J20: 2 | K20: https://drive.google.com/open?id=13VmM-nauyvTgUS2cdrxWQoj8aSSkaXDB
A21: 46137.62 | B21: Vinod C S | C21: Male | D21: 9821441168 | E21: 9821441229 | F21: Thane | G21: Maharashtra | H21: Dorm Cottage – Rs 1500/- per person | I21: 6/5/2026 | J21: 1 | K21: https://drive.google.com/open?id=1sd4f8brOD0IpdxyoN4IwO0qv7qH8qWZm
A22: 46139.428 | B22: Prashant Bagwe | C22: Male | D22: 8097001105 | E22: Meenal | F22: Thane | G22: Maharashtra | H22: Dorm Cottage – Rs 1500/- per person | I22: 6/5/2026 | J22: 1 | K22: https://drive.google.com/open?id=1jKiaJYLqdkydGaedsS66IzmMtqhrjrFl
A23: 46140.625 | B23: Apoorva Gawalikar | C23: Male | D23: 8600928527 | E23: 7715890930 | F23: Navi Mumbai | G23: Maharashtra | H23: Dorm Cottage – Rs 1500/- per person | I23: 6/5/2026 | J23: 2 | K23: https://drive.google.com/open?id=11DJ9klqkEumc5xl6CiFQpTOm7qX8HyK3
A24: 46144.62 | B24: SAMBHAJI Deshmukh | C24: Male | D24: 9167393782 | E24: 9167394582 | F24: THANE | G24: Maharashtra | H24: Dorm Cottage – Rs 1500/- per person | I24: 6/5/2026 | J24: 1 | K24: https://drive.google.com/open?id=1Qd6YVayfqQjFfpJBd_wD1o57cZxbihLE
A25: 46148.822 | B25: Jai Parab | C25: Male | D25: 7021120768 | E25: 9920060731 | F25: Mumbaj | G25: Mahar | H25: Dorm Cottage – Rs 1500/- per person | I25: 6/5/2026 | J25: 2 | K25: https://drive.google.com/open?id=12IPWEQax6urBXkuTYrqewaUXCWO4Vz7_
A26: 46150.476 | B26: Guruprasad Bandagi | C26: Male | D26: 7406554191 | E26: 8668989422 | F26: Solapur | G26: Maharashtra | H26: Dorm Cottage – Rs 1500/- per person | I26: 6/5/2026 | J26: 1 | K26: https://drive.google.com/open?id=1rl7-f3IOz7cGHb5r8nfbvP9TTkNMnBFy
A27: 46154.708 | B27: Gulbinder Singh Multani | C27: Male | D27: 9757086690 | E27: +91 79-77827090 | F27: Thane | G27: Maharashtra | H27: Dorm Cottage – Rs 1500/- per person | I27: 6/5/2026 | J27: 1 | K27: https://drive.google.com/open?id=14ZmSyAr_Ysvr9SPWvqe7pOpYTbgeTwdI
A28: 46155.497 | B28: Sharath Bhoja | C28: Male | D28: 7763807445 | E28: 7868966404 | F28: Jamshedpur | G28: Jharkhand | H28: Dorm Cottage – Rs 1500/- per person | I28: 6/5/2026 | J28: 1 | K28: https://drive.google.com/open?id=1gl6fBGwW73C89BSUxWTwoVwgxoNg_TJT
A29: 46155.507 | B29: Dr.Amlan Swain | C29: Male | D29: 7033095071 | E29: 7763807445 | F29: Jamshedpur | G29: Jharkhand | H29: Dorm Cottage – Rs 1500/- per person | I29: 6/5/2026 | J29: 1 | K29: https://drive.google.com/open?id=1YrIrrnQiLNWyTu1sMsBr6-TIUeEz9Hd0
A30: 46155.509 | B30: Dr.Bhanu Swain | C30: Male | D30: 9471519719 | E30: 7763807445 | F30: Jamshedpur | G30: Jharkhand | H30: Dorm Cottage – Rs 1500/- per person | I30: 6/5/2026 | J30: 1 | K30: https://drive.google.com/open?id=1CHOobIqQeNN7qaGutfJPzni_YnL2HgLO
A31: 46155.511 | B31: Vini Bhagat | C31: Female | D31: 8092095867 | E31: 7868966404 | F31: Jamshedpur | G31: Jharkhand | H31: Dorm Cottage – Rs 1500/- per person | I31: 6/5/2026 | J31: 1 | K31: https://drive.google.com/open?id=1QuyRW3BiUUE9P5X_chBWeEzdcKuRXwk8
A32: 46155.514 | B32: Dr.Y Ramamurthy | C32: Male | D32: 9204058852 | E32: 7763807445 | F32: Jamshedpur | G32: Jharkhand | H32: Dorm Cottage – Rs 1500/- per person | I32: 6/5/2026 | J32: 1 | K32: https://drive.google.com/open?id=1n0GByA6wf0me6nikZsL9JzJL9RtRz87b
A33: 46158.58 | B33: Debleena Pramanik | C33: Female | D33: 9051960778 | E33: 8240534140 | F33: Mumbai | G33: Maharashtra | H33: Dorm Cottage – Rs 1500/- per person | I33: 6/5/2026 | J33: 1 | K33: https://drive.google.com/open?id=1Y9nYdpowBffepEa0A7wCFxFI9-I7Zv6N
A34: 46158.589 | B34: Rajkamal Rabha | C34: Male | D34: 9613348932 | E34: 9957172329 | F34: Mumbai | G34: Maharashtra | H34: Dorm Cottage – Rs 1500/- per person | I34: 6/5/2026 | J34: 2 | K34: https://drive.google.com/open?id=156Z1PS-_KoeThO5QpBVVG_a8-RIrmC5F
A35: 46159.41 | B35: Akshaydeep Singh Gandhi | C35: Male | D35: 9870386560 | E35: 9820861159 | F35: Mumbai | G35: Maharashtra | H35: Dorm Cottage – Rs 1500/- per person | I35: 6/5/2026 | J35: 1 | K35: https://drive.google.com/open?id=1wkYmgayg_zkyvAn0WSU4AgfmtdyATIJH
A36: 46159.413 | B36: Yuvraj Dhawan | C36: Male | D36: 9773192330 | E36: 9870386560 | F36: Mumbai | G36: Maharashtra | H36: Dorm Cottage – Rs 1500/- per person | I36: 6/5/2026 | J36: 1 | K36: https://drive.google.com/open?id=1BvOikVxTpRZb6t83KEyxaUZeyMvVMZSc
A37: 46163.496 | B37: RAVIKANNA VIMAL | C37: Male | D37: 9969777975 | E37: Priya ravi | F37: Chennai | G37: Tamilnadu | H37: 3 person Tent - Complete Tent - Rs 3000/- | I37: 6/5/2026 | J37: 1 | K37: https://drive.google.com/open?id=1BN4i0ooMtZUyZNZZeHYZTmLT3tZqlnJ7
A38: 46163.512 | B38: Vijay Rambariki | C38: Male | D38: 9920600579 | E38: 9820398065 | F38: Navi Mumbai | G38: Maharashtra | H38: Dorm Cottage – Rs 1500/- per person | I38: 6/5/2026 | J38: 1 | K38: https://drive.google.com/open?id=1tQQCXUJrdUtStqfvS-NcaVYLxZreLNXo
A39: 46163.785 | B39: Ankit Loni | C39: Male | D39: 8310371388 | E39: 9538878311 | F39: bangalore | G39: Karnataka | H39: Dorm Cottage – Rs 1500/- per person | I39: 6/5/2026 | J39: 1 | K39: https://drive.google.com/open?id=1eGpNPrYamXgxC1WyzCTKqVKdYB5Cc0Xa
A40: 46163.797 | B40: Anirban dhar | C40: Male | D40: 9836858785 | E40: Aditi | F40: Kolkata | G40: West bengal | H40: 3 person Tent - Complete Tent - Rs 3000/- | I40: 6/5/2026 | J40: 2 | K40: https://drive.google.com/open?id=1mWPC5j9T_LV4USnVtXSZ_bPL1PkapRua
...

Sheet Sheet1
A1: Full Name | B1: Column 1 | C1: Name | D1: Phone Number
A2: Sandeep Sudhir Kale | C2: ="MAWLA 2026- "&(A2) | D2: 7506655137
A3: Ajin P Suresh | C3: ="MAWLA 2026- "&(A3) | D3: 8891426550
A4: Nithin D S | C4: ="MAWLA 2026- "&(A4) | D4: 7259874849
A5: Pooja Tanaji Budhawale | C5: ="MAWLA 2026- "&(A5) | D5: 9975047905
A6: SUDEEP VITHAL DALVI | C6: ="MAWLA 2026- "&(A6) | D6: 8080838036
A7: Swapnil Pralhad Patil | C7: ="MAWLA 2026- "&(A7) | D7: 9967022249
A8: Bhavik Solanki | C8: ="MAWLA 2026- "&(A8) | D8: 9727046243
A9: Amit Sanjay Singh Nagarkoti | C9: ="MAWLA 2026- "&(A9) | D9: 7715890930
A10: Vinod C S | C10: ="MAWLA 2026- "&(A10) | D10: 9821441168
A11: Prashant Bagwe | C11: ="MAWLA 2026- "&(A11) | D11: 8097001105
A12: Apoorva Gawalikar | C12: ="MAWLA 2026- "&(A12) | D12: 8600928527
A13: SAMBHAJI Deshmukh | C13: ="MAWLA 2026- "&(A13) | D13: 9167393782
... A59: Mamta Joshi | C59: ="MAWLA 2026- "&(A59) | D59: 9997398115

Sheet Sheet2
A1: Name | B1: Phone Number
A2: =Sheet1!C2 | B2: 7506655137
A3: =Sheet1!C3 | B3: 8891426550
A4: =Sheet1!C4 | B4: 7259874849
A5: =Sheet1!C5 | B5: 9975047905
A6: =Sheet1!C6 | B6: 8080838036
A7: =Sheet1!C7 | B7: 9967022249
A8: =Sheet1!C8 | B8: 9727046243
A9: =Sheet1!C9 | B9: 7715890930
A10: =Sheet1!C10 | B10: 9821441168
A11: =Sheet1!C11 | B11: 8097001105
A12: =Sheet1!C12 | B12: 8600928527
A13: =Sheet1!C13 | B13: 9167393782
... A59: =Sheet1!C59 | B59: 9997398115
A60: =Sheet1!C60
A61: =Sheet1!C61

Sheet Sheet3
A1: Full Name | B1: Gender | C1: Phone Number | D1: Emergency Contact | E1: City (travelling from) | F1: State (travelling from) | G1: Accommodation (per night charges) | H1: Date of Check In (MM/DD/YYYY) | I1: No of nights of stay | J1: Upload Payment Screenshot to Confirm Accommodation | K1: Comments
A2: Sridhar | B2: Male | C2: 9500057386 | D2: 8825867669 | E2: Chennai | F2: Tamil Nadu | G2: Bamboo House – Rs 1400/- per person | H2: 46177 | I2: 1
A3: Saravana Kumar | B3: Male | C3: 9791587899 | D3: 9842681118 | E3: Chennai | F3: Tamil Nadu | G3: Bamboo House – Rs 1400/- per person | H3: 46177 | I3: 1
A4: Aravind E | B4: Male | C4: 9940644237 | D4: 9789580327 | E4: Chennai | F4: Tamil Nadu | G4: Bamboo House – Rs 1400/- per person | H4: 46177 | I4: 1
A5: Aravind | B5: Male | C5: 9952329678 | D5: 9003254840 | E5: Chennai | F5: Tamil Nadu | G5: Bamboo House – Rs 1400/- per person | H5: 46177 | I5: 1
A6: Sarathy | B6: Male | C6: 9025472014 | D6: 9790974930 | E6: Chennai | F6: Tamil Nadu | G6: Bamboo House – Rs 1400/- per person | H6: 46177 | I6: 1
A7: Nithin | B7: Male | C7: 9994571927 | D7: 7708555661 | E7: Chennai | F7: Tamil Nadu | G7: Bamboo House – Rs 1400/- per person | H7: 46177 | I7: 1
A8: Narayanaswamy | B8: Male | C8: 9842681118 | D8: 9994633903 | E8: Chennai | F8: Tamil Nadu | G8: Bamboo House – Rs 1400/- per person | H8: 46177 | I8: 1
A9: Anitha | B9: Female | C9: 9743444459 | D9: 8754304879 | E9: Bangalore | F9: Karnataka | G9: Dorm Cottage – Rs 1500/- per person | H9: 46177 | I9: 1
A10: Mani | B10: Male | C10: 9043779739 | D10: 9746551486 | E10: Chennai | F10: Tamil Nadu | G10: Bamboo House – Rs 1400/- per person | H10: 46177 | I10: 1
A11: Manoj | B11: Male | C11: 9020033302 | D11: 9789580327 | E11: Cochin | F11: Kerala | G11: Bamboo House – Rs 1400/- per person | H11: 46177 | I11: 1
A12: Sadiq | B12: Male | C12: 9003254840 | D12: 9095021621 | E12: Chennai | F12: Tamil Nadu | G12: Bamboo House – Rs 1400/- per person | H12: 46178 | I12: 1
A13: Ravindran | B13: Male | C13: 9790974930 | D13: 9619209239 | E13: Chennai | F13: Tamil Nadu | G13: Bamboo House – Rs 1400/- per person | H13: 46178 | I13: 1
... A33: Sanjay | B33: Male | C33: 9746551486 | D33: 9500044027 | E33: Chennai | F33: Tamil Nadu | G33: Dorm Cottage – Rs 1500/- per person | H33: 46178 | I33: 1

Sheet Sheet4
A1: =#REF! | B1: 8310371388
A2: =Sheet1!C1 | B2: 9836858785
A3: =Sheet1!C2 | B3: 8130845518
A4: =Sheet1!C3 | B4: 8806723534
A5: =Sheet1!C4 | B5: 7719305093
A6: =Sheet1!C5 | B6: 9880396502
A7: =Sheet1!C6 | B7: 9746593676
A8: =Sheet1!C7 | B8: 7338426300
A9: =Sheet1!C8 | B9: 9997398115

Sheet Localhost Audit
A1: Section | B1: Workbook | C1: Sheet | D1: Row | E1: Name | F1: Field / Issue | G1: Old / Detail | H1: New / Status
A2: Corrected | B2: Mawla Ghati Ultra 2026 (Responses).xlsx | C2: Form Responses 1 | D2: 27 | E2: Gulbinder Singh Multani | F2: No of nights of stay | G2: One | H2: 1
A3: Summary | B3: Mawla Ghati Ultra 2026 (Responses).xlsx | F3: Matched rows | G3: 85
A4: Summary | B4: Mawla Ghati Ultra 2026 (Responses).xlsx | F4: Corrections | G4: 1
A5: Summary | B5: Mawla Ghati Ultra 2026 (Responses).xlsx | F5: Review items | G5: 0
